Workbook

Sheet DCF
A1: Johnson and Johnson DCF | R1: Inputs
A2: Ticker | B2: JNJ | E2: Share Price Estimate | F2: =B95 -> 412.9647 | R2: ST Growth Rate | S2: =MEDIAN(E23:H23) -> 0.034582793
A3: Date | B3: 45600 | E3: Current Share Price | F3: 154.01 | G3: =F3/F2-1 -> -0.62706255 | H3: =IF(G3>0, "overvalued", "undervalued") -> undervalued | R3: LT Growth Rate | S3: 0.02
A5: Assumptions
E6: Conservative (1) | G6: Base (2) | I6: Optimistic (3)
A7: Switches (#) | E7: Revenue 2024 | F7: 0.01 | G7: Revenue 2024 | H7: 0.03 | I7: Revenue 2024 | J7: 0.08
A8: Revenue | C8: 2 | E8: Revenue 2033 | F8: 0.02 | G8: Revenue 2033 | H8: 0.04 | I8: Revenue 2033 | J8: 0.05
A9: EBIT Margin | C9: 2 | E9: EBIT | F9: 0.08 | G9: EBIT | H9: =GEOMEAN(E26:H26) -> 0.2584536 | I9: EBIT | J9: 0.3
A10: Taxes | C10: 2 | E10: Taxes | F10: 0.21 | G10: Taxes | H10: =AVERAGE(D30:H30) -> 0.18720914 | I10: Taxes | J10: 0
A11: D&A | C11: 2 | E11: D&A | F11: =H11-0.005 -> 0.080344178 | G11: D&A | H11: =AVERAGE(D69:H69) -> 0.085344178 | I11: D&A | J11: =H11+0.005 -> 0.090344178
A12: CapEx | C12: 2 | E12: CapEx | F12: =H12+0.01 -> 0.015153901 | G12: CapEx | H12: =AVERAGE(D75:H75) -> 0.0051539013 | I12: CapEx | J12: =H12-0.01 -> -0.0048460987
A13: NWC | C13: 2 | E13: NWC | F13: =H13 -> -0.01113257 | G13: NWC | H13: =AVERAGE(E43:H43) -> -0.01113257 | I13: NWC | J13: =H13 -> -0.01113257
A14: WACC | C14: 2 | E14: WACC | F14: 0.09 | G14: WACC | H14: 0.05 | I14: WACC | J14: 0.04
A15: TGR | C15: 2 | E15: TGR | G15: TGR | I15: TGR
A17: Valuation Assumptions
A18: WACC | C18: 0.05
A19: TGR | C19: 0.03
A21: Income Statement | D21: 2019 | E21: 2020 | F21: 2021 | G21: 2022 | H21: 2023 | I21: 2024 | J21: 2025 | K21: 2026 | L21: 2027 | M21: 2028 | N21: 2029 | R21: Average EBIT / Rev | S21: =GEOMEAN(E26:H26) -> 0.2584536
A22: Revenue | D22: ='Income Statement'!B10 -> 82113 | E22: ='Income Statement'!C10 -> 82572 | F22: ='Income Statement'!D10 -> 93758 | G22: ='Income Statement'!E10 -> 80062 | H22: ='Income Statement'!F10 -> 85152
A23: % Growth | E23: =(E22/D22)-1 -> 0.0055898579 | F23: =(F22/E22)-1 -> 0.13546965 | G23: =(G22/F22)-1 -> -0.1460782 | H23: =(H22/G22)-1 -> 0.063575729
A25: EBIT | D25: ='Income Statement'!B20 -> 21550 | E25: ='Income Statement'!C20 -> 20468 | F25: ='Income Statement'!D20 -> 24481 | G25: ='Income Statement'!E20 -> 21207 | H25: ='Income Statement'!F20 -> 22162
A26: % of revenue | D26: =D25/D22 -> 0.26244322 | E26: =E25/E22 -> 0.24788064 | F26: =F25/F22 -> 0.26110839 | G26: =G25/G22 -> 0.26488222 | H26: =H25/H22 -> 0.260264
A28: Taxes (Reported) | D28: ='Income Statement'!B41 -> 2209 | E28: ='Income Statement'!C15 -> 4700 | F28: ='Income Statement'!D15 -> 4700 | G28: ='Income Statement'!E15 -> 3900 | H28: ='Income Statement'!F15 -> 4500
A29: Taxes (Effective) | D29: ='Income Statement'!B40 -> 17328 | E29: =E25*(1-0.21) -> 16169.72 | F29: =F25*(1-0.21) -> 19339.99 | G29: =G25*(1-0.21) -> 16753.53 | H29: =H25*(1-0.21) -> 17507.98
A30: Tax Rate | D30: =D28/D29 -> 0.12748153 | E30: =E28/E25 -> 0.22962673 | F30: =F28/F25 -> 0.19198562 | G30: =G28/G25 -> 0.18390154 | H30: =H28/H25 -> 0.20305027
A33: Cash Flow Items | D33: 2019 | E33: 2020 | F33: 2021 | G33: 2022 | H33: 2023 | I33: 2024 | J33: 2025 | K33: 2026 | L33: 2027 | M33: 2028 | N33: 2029
A34: D&A | D34: ='Statement of Cash Flows'!B6 -> 7009 | E34: ='Statement of Cash Flows'!C6 -> 7231 | F34: ='Statement of Cash Flows'!D6 -> 7390 | G34: ='Statement of Cash Flows'!E6 -> 6970 | H34: ='Statement of Cash Flows'!F6 -> 7486
A35: % of revenue | D35: =D34/D22 -> 0.085357982 | E35: =E34/E22 -> 0.087572058 | F35: =F34/F22 -> 0.078819941 | G35: =G34/G22 -> 0.08705753 | H35: =H34/H22 -> 0.087913378
A36: % of CAPEX | E36: =E34/E38 -> 6.5261733 | F36: =F34/F38 -> 37.704082 | G36: =G34/G38 -> -7.1122449 | H36: =H34/H38 -> 3.9070981
A38: CAPEX | D38: ='Balance Sheet'!B51 -> 0 | E38: ='Balance Sheet'!C51 -> 1108 | F38: ='Balance Sheet'!D51 -> 196 | G38: ='Balance Sheet'!E51 -> -980 | H38: ='Balance Sheet'!F51 -> 1916
A39: % of revenue | D39: =D38/D22 -> 0 | E39: =E38/E22 -> 0.013418592 | F39: =F38/F22 -> 0.0020904883 | G39: =G38/G22 -> -0.012240514 | H39: =H38/H22 -> 0.022500939
A41: NWC | D41: ='Balance Sheet'!B52 -> 9310 | E41: ='Balance Sheet'!C52 -> 8744 | F41: ='Balance Sheet'!D52 -> 15753 | G41: ='Balance Sheet'!E52 -> -508 | H41: ='Balance Sheet'!F52 -> 7213
A42: Change in NWC | E42: =E41-D41 -> -566 | F42: =F41-E41 -> 7009 | G42: =G41-F41 -> -16261 | H42: =H41-G41 -> 7721
A43: % of revenue | E43: =E42/E22 -> -0.0068546238 | F43: =F42/F22 -> 0.074756287 | G43: =G42/G22 -> -0.20310509 | H43: =H42/H22 -> 0.090673149
A44: % of change in revenue | E44: =E42/(E22-D22) -> -1.2331155 | F44: =F42/(F22-E22) -> 0.6265868 | G44: =G42/(G22-F22) -> 1.187281 | H44: =H42/(H22-G22) -> 1.5168959
I46: 1 | J46: 2 | K46: 3 | L46: 4 | M46: 5 | N46: 6 | O46: 7 | P46: 8 | Q46: 9 | R46: 10
A47: DCF | D47: 2019 | E47: 2020 | F47: 2021 | G47: 2022 | H47: 2023 | I47: 2024 | J47: 2025 | K47: 2026 | L47: 2027 | M47: 2028 | N47: 2029 | O47: 2030 | P47: 2031 | Q47: 2032 | R47: 2033
A48: Revenue | D48: =D22 -> 82113 | E48: =E22 -> 82572 | F48: =F22 -> 93758 | G48: =G22 -> 80062 | H48: =H22 -> 85152 | I48: =H48*(1+I49) -> 87706.56 | J48: =I48*(1+J49) -> 90305.273 | K48: =J48*(1+K49) -> 92947.538 | L48: =K48*(1+L49) -> 95632.689 | M48: =L48*(1+M49) -> 98359.992 | N48: =M48*(1+N49) -> 101128.64 | O48: =N48*(1+O49) -> 103937.77 | P48: =O48*(1+P49) -> 106786.44 | ... R48: =Q48*(1+R49) -> 112598.26
A49: % growth | E49: =E23 -> 0.0055898579 | F49: =F23 -> 0.13546965 | G49: =G23 -> -0.1460782 | H49: =H23 -> 0.063575729 | I49: =OFFSET(I49,$C$8,0) -> 0.03 | J49: =OFFSET(J49,$C$8,0) -> 0.02962963 | K49: =OFFSET(K49,$C$8,0) -> 0.029259259 | L49: =OFFSET(L49,$C$8,0) -> 0.028888889 | M49: =OFFSET(M49,$C$8,0) -> 0.028518519 | N49: =OFFSET(N49,$C$8,0) -> 0.028148148 | O49: =OFFSET(O49,$C$8,0) -> 0.027777778 | P49: =OFFSET(P49,$C$8,0) -> 0.027407407 | ... R49: =OFFSET(R49,$C$8,0) -> 0.026666667
A50: Conservative Case | I50: =F7 -> 0.01 | J50: =I50-(($I50-$R50)/9) -> 0.011111111 | K50: =J50-(($I50-$R50)/9) -> 0.012222222 | L50: =K50-(($I50-$R50)/9) -> 0.013333333 | M50: =L50-(($I50-$R50)/9) -> 0.014444444 | N50: =M50-(($I50-$R50)/9) -> 0.015555556 | O50: =N50-(($I50-$R50)/9) -> 0.016666667 | P50: =O50-(($I50-$R50)/9) -> 0.017777778 | Q50: =P50-(($I50-$R50)/9) -> 0.018888889 | R50: =F8 -> 0.02
...

Sheet Income Statement
A1: Johnson & Johnson (JNJ)
A2: $152.74
A5: Johnson & Johnson
A6: JNJ 478160104 2475833 NYSE Common stock
A7: Source: FactSet Fundamentals
B8: 2019 | C8: 2020 | D8: 2021 | E8: 2022 | F8: 2023
A10: Sales | B10: 82113 | C10: 82572 | D10: 93758 | E10: 80062 | F10: 85152
A11: Cost of Goods Sold (COGS) incl. D&A | B11: 27135 | C11: 27998 | D11: 29874 | E11: 24325 | F11: 26430
A12: COGS excluding D&A | B12: 20126 | C12: 20767 | D12: 22484 | E12: 17355 | F12: 18944
A13: Depreciation & Amortization Expense | B13: 7009 | C13: 7231 | D13: 7390 | E13: 6970 | F13: 7486
A14: Depreciation | B14: 2509 | C14: 2531 | D14: 2690 | E14: 3070 | F14: 2986
A15: Amortization of Intangibles | B15: 4500 | C15: 4700 | D15: 4700 | E15: 3900 | F15: 4500
A16: Gross Income | B16: 54978 | C16: 54574 | D16: 63884 | E16: 55737 | F16: 58722
A17: SG&A Expense | B17: 33428 | C17: 34106 | D17: 39403 | E17: 34530 | F17: 36560
A18: Research & Development | B18: 11250 | C18: 12022 | D18: 14744 | E18: 14284 | F18: 15048
A19: Other SG&A | B19: 22178 | C19: 22084 | D19: 24659 | E19: 20246 | F19: 21512
A20: EBIT (Operating Income) | B20: 21550 | C20: 20468 | D20: 24481 | E20: 21207 | F20: 22162
A21: Nonoperating Income - Net | B21: 2555 | C21: 629 | D21: 2404 | E21: 2655.2 | F21: 3386.3
... A27: Unusual Expense - Net | B27: 6008 | C27: 3876 | D27: 3350 | E27: 3662.2 | F27: 9309.3
A28: Impairments
A29: Other Intangibles | B29: 0 | C29: 0 | D29: 0 | E29: 0 | F29: 0
A30: Property,Plant & Equipment
A31: Exceptional Provisions | C31: -1148 | D31: 0 | F31: 0
A32: Restructuring Expense | B32: 566 | C32: 447 | D32: 452 | E32: 975.2 | F32: 1198.3
A33: Legal Claim Expense | B33: 5100 | C33: 5100 | D33: 2300 | E33: 900 | F33: 6900
A34: Unrealized Valuation Gain/Loss | B34: 548 | C34: 704 | D34: 302 | E34: -1004 | F34: -898
A35: Investments | B35: 533 | C35: 527 | D35: 198 | E35: -538 | F35: -968
A36: Hedges/Derivatives | B36: 15 | C36: 177 | D36: 104 | E36: -466 | F36: 70
A37: Excpl Chrgs - Others | B37: 890 | C37: 181 | D37: 900 | E37: 783 | F37: 313
A38: Acquired In-Process R&D | B38: 890 | C38: 181 | D38: 900 | E38: 783 | F38: 313
A39: Other Unusual Expense
A40: Pretax Income | B40: 17328 | C40: 16497 | D40: 22776 | E40: 19359 | F40: 15062
A41: Income Taxes | B41: 2209 | C41: 1783 | D41: 1898 | E41: 2989 | F41: 1736
A42: Income Taxes - Current Domestic | B42: 1941 | C42: 1026 | D42: 1525 | E42: 2274 | F42: 2705
A43: Income Taxes - Current Foreign | B43: 2744 | C43: 1898 | D43: 2452 | E43: 2295 | F43: 3090
A44: Income Taxes - Deferred Domestic | B44: -814 | C44: -76 | D44: 583 | E44: -1990 | F44: -3440
A45: Income Taxes - Deferred Foreign | B45: -1662 | C45: -1065 | D45: -2662 | E45: 410 | F45: -619
A46: Consolidated Net Income | B46: 15119 | C46: 14714 | D46: 20878 | E46: 16370 | F46: 13326
A47: Net Income | B47: 15119 | C47: 14714 | D47: 20878 | E47: 16370 | F47: 13326
A48: Discontinued Operations | B48: 0 | C48: 0 | D48: 0 | E48: 1571 | F48: 843
...

Sheet Balance Sheet
A1: Consolidated Balance Sheets - USD ($) $ in Millions | B1: Dec. 31, 2019 | C1: Dec. 31, 2020 | D1: Dec. 31, 2021 | E1: Dec. 31, 2022 | F1: Dec. 31, 2023
A2: Current Assets
A3: Cash and cash equivalents (Notes 1 and 2) | B3: 17305 | C3: 13985 | D3: 14487 | E3: 12889 | F3: 21859
A4: Marketable securities (Notes 1 and 2) | B4: 1982 | C4: 11200 | D4: 17121 | E4: 9392 | F4: 1068
A5: Accounts receivable trade, less allowances | B5: 14481 | C5: 13576 | D5: 15283 | E5: 14039 | F5: 14873
A6: Inventories (Notes 1 and 3) | B6: 9020 | C6: 9344 | D6: 10387 | E6: 10268 | F6: 11181
A7: Prepaid expenses and other receivables | B7: 2392 | C7: 3132 | D7: 3701 | E7: 2876 | F7: 4514
A8: Current assets of discontinued operations | E8: 5830
A9: Assets held for sale (Note 20) | B9: 94
A10: Total Current Assets | B10: =SUM(B3:B9) -> 45274 | C10: =SUM(C3:C9) -> 51237 | D10: =SUM(D3:D9) -> 60979 | E10: =SUM(E3:E9) -> 55294 | F10: =SUM(F3:F9) -> 53495
A11: Property, plant and equipment, net (Notes 1 and 4) | B11: 17658 | C11: 18766 | D11: 18962 | E11: 17982 | F11: 19898
A12: Intangible assets, net (Notes 1 and 5) | B12: 47643 | C12: 53402 | D12: 46392 | E12: 38489 | F12: 34175
A13: Goodwill (Notes 1 and 5) | B13: 33639 | C13: 36393 | D13: 35246 | E13: 36047 | F13: 36558
A14: Deferred taxes on income (Note 8) | B14: 7819 | C14: 8534 | D14: 10223 | E14: 8947 | F14: 9279
A15: Other assets | B15: 5695 | C15: 6562 | D15: 10216 | E15: 9212 | F15: 14153
A16: Noncurrent assets of discontinued operations | E16: 21407 | F16: —
A17: Total Assets | B17: =SUM(B10:B16) -> 157728 | C17: =SUM(C10:C16) -> 174894 | D17: =SUM(D10:D16) -> 182018 | E17: =SUM(E10:E16) -> 187378 | F17: =SUM(F10:F16) -> 167558
A20: Liabilities and Shareholders’ Equity
A21: Current Liabilities
A22: Loans and notes payable (Note 7) | B22: 1202 | C22: 2631 | D22: 3766 | E22: 12756 | F22: 3451
A23: Accounts payable | B23: 8544 | C23: 9505 | D23: 11055 | E23: 9889 | F23: 9632
A24: Accrued liabilities | B24: 9715 | C24: 13968 | D24: 13612 | E24: 10719 | F24: 10212
A25: Accrued rebates, returns, and promotions | B25: 10883 | C25: 11513 | D25: 12095 | E25: 13579 | F25: 16001
A26: Accrued compensation and employee obligations | B26: 3354 | C26: 3484 | D26: 3586 | E26: 3049 | F26: 3993
A27: Accrued taxes on income (Note 8) | B27: 2266 | C27: 1392 | D27: 1112 | E27: 2220 | F27: 2993
A28: Current liabilities of discontinued operations | E28: 3590 | F28: —
A29: Total Current Liabilities | B29: =SUM(B22:B28) -> 35964 | C29: =SUM(C22:C28) -> 42493 | D29: =SUM(D22:D28) -> 45226 | E29: =SUM(E22:E28) -> 55802 | F29: =SUM(F22:F28) -> 46282
A30: Long-term debt (Note 7) | B30: 26494 | C30: 32635 | D30: 29985 | E30: 26886 | F30: 25881
A31: Deferred taxes on income (Note 8) | B31: 5958 | C31: 7214 | D31: 7487 | E31: 3991 | F31: 3193
A32: Employee-related obligations (Notes 9 and 10) | B32: 10663 | C32: 10771 | D32: 8898 | E32: 6542 | F32: 7149
A33: Long-term taxes payable (Note 8) | B33: 7444 | C33: 6559 | D33: 5713 | E33: 4306 | F33: 2881
A34: Other liabilities | B34: 11734 | C34: 11944 | D34: 10686 | E34: 10146 | F34: 13398
A35: Noncurrent liabilities of discontinued operations | E35: 2901 | F35: —
A36: Total Liabilities | B36: =SUM(B29:B35) -> 98257 | C36: =SUM(C29:C35) -> 111616 | D36: =SUM(D29:D35) -> 107995 | E36: =SUM(E29:E35) -> 110574 | F36: =SUM(F29:F35) -> 98784
A37: Commitments and Contingencies (Note 21)
A40: Shareholders’ Equity
A41: Preferred stock | B41: — | C41: — | D41: — | E41: — | F41: —
A42: Common stock — par value $1.00 per share (Note 12) | B42: 3120 | C42: 3120 | D42: 3120 | E42: 3120 | F42: 3120
A43: Accumulated other comprehensive income (loss) (Note 13) | B43: -15891 | C43: -15242 | D43: -13058 | E43: -12967 | F43: -12527
A44: Retained earnings | B44: 110659 | C44: 113890 | D44: 123060 | E44: 128345 | F44: 153843
...

Sheet Statement of Cash Flows
A2: Consolidated Statements of Cash Flows - USD ($) $ in Millions | B2: Dec. 31, 2019 | C2: Dec. 31, 2020 | D2: Dec. 31, 2021 | E2: Dec. 31, 2022 | F2: Dec. 31, 2023
A3: Cash Flows from Operating Activities
A4: Net earnings | B4: 15119 | C4: 14714 | D4: 20878 | E4: 17941 | F4: 35153
A5: Adjustments to reconcile net earnings to cash flows:
A6: Depreciation and amortization of property and intangibles | B6: 7009 | C6: 7231 | D6: 7390 | E6: 6970 | F6: 7486
A7: Stock-based compensation | B7: 977 | C7: 1005 | D7: 1135 | E7: 1138 | F7: 1162
A8: Asset write-downs | B8: 1096 | C8: 233 | D8: 989 | E8: 1216 | F8: 1295
A9: Contingent consideration reversal | B9: — | C9: -1148 | D9: — | E9: — | F9: 483
A10: Charge for purchase of in-process research and development assets | D10: — | E10: — | F10: -20984
A11: Gain on Kenvue separation | D11: -617 | E11: -380 | F11: -117
A12: Net gain on sale of assets/businesses | B12: -2154 | C12: -111 | D12: -2079 | E12: -1663 | F12: -4194
A13: Deferred tax provision | B13: -2476 | C13: -1141 | D13: -48 | E13: -17 | F13: —
A14: Credit losses and accounts receivable allowances | B14: -20 | C14: 63 | D14: -27 | E14: 140 | F14: 0
A15: Decrease/(Increase) in accounts receivable | B15: -289 | C15: 774 | D15: -2402 | E15: -1290 | F15: -624
A16: Increase in inventories | B16: -277 | C16: -265 | D16: -1248 | E16: -2527 | F16: -1323
A17: Increase in accounts payable and accrued liabilities | B17: 4060 | C17: 5141 | D17: 2437 | E17: 1098 | F17: 2346
A18: Increase in other current and non-current assets | B18: -1054 | C18: -3704 | D18: -1964 | E18: 687 | F18: -3480
A19: Increase/(Decrease) in other current and non-current liabilities | B19: 1425 | C19: 744 | D19: -1061 | E19: -1979 | F19: 5588
A20: Net cash flows from operating activities | B20: 23416 | C20: 23536 | D20: 23410 | E20: 21194 | F20: 22791
D21: 793 | E21: 1131 | F21: 1532
A22: Cash Flows from Investing Activities | D22: 11497 | E22: 14724 | F22: 13256
A23: Additions to property, plant, and equipment | B23: -3498 | C23: -3347 | D23: -3652 | E23: -4009 | F23: -4543
A24: Proceeds from disposal of assets/businesses, net | B24: 3265 | C24: 305 | D24: 711 | E24: 543 | F24: 358
A25: Acquisitions, net of cash acquired | B25: -5810 | C25: -7323 | D25: -60 | E25: -17652 | F25: —
A26: Purchases of in-process research and development assets (Note 18) | D26: — | E26: — | F26: -470
A27: Purchases of investments | B27: -3920 | C27: -21089 | D27: -30394 | E27: -32384 | F27: -10906
A28: Sales of investments | B28: 3387 | C28: 12137 | D28: 25006 | E28: 41609 | F28: 19390
A29: Credit support agreements activity, net | B29: 338 | C29: -987 | D29: 214 | E29: -249 | F29: -2963
A30: Other (primarily licenses and milestones) | B30: 44 | C30: -521 | D30: -508 | E30: -229 | F30: 12
A31: Net cash used by investing activities | B31: -6194 | C31: -20825 | D31: -8683 | E31: -12371 | F31: 878
D32: 0 | E32: 0 | F32: 138
A33: Cash Flows from Financing Activities | D33: 6 | E33: 76 | F33: 0
A34: Dividends to shareholders | B34: -9917 | C34: -10481 | D34: -11032 | E34: -11682 | F34: -11770
A35: Repurchase of common stock | B35: -6746 | C35: -3221 | D35: -3456 | E35: -6035 | F35: -5054
A36: Proceeds from short-term debt | B36: 39 | C36: 3391 | D36: 1997 | E36: 16134 | F36: 13743
A37: Repayment of short-term debt | B37: -100 | C37: -2663 | D37: -1190 | E37: -6550 | F37: -22973
A38: Proceeds from long-term debt, net of issuance costs | B38: 3 | C38: 7431 | D38: 5 | E38: 2 | F38: —
A39: Repayment of long-term debt | B39: -2823 | C39: -1064 | D39: -1802 | E39: -2134 | F39: -1551
A40: Proceeds from stock options/employee withholding tax | B40: 954 | C40: 1114 | D40: 1036 | E40: 1329 | F40: 1094
A41: Credit support agreements activity, net | B41: 100 | C41: -333 | D41: 281 | E41: -28 | F41: -219
...

Sheet WACC Calculation
A1: Estimate Market Beta (CAPM)
A2: SUMMARY OUTPUT
A4: Regression Statistics
A5: Multiple R | B5: 0.15500287
A6: R Square | B6: 0.02402589
A7: Adjusted R Square | B7: 0.022077838
A8: Standard Error | B8: 0.0097766556
A9: Observations | B9: 503 | K9: CAPM Estimated Required Return on Equity
K10: =A30+(B19*A25) -> 0.050449503
A11: ANOVA
B12: df | C12: SS | D12: MS | E12: F | F12: Significance F | K12: Estimated Yield on Bonds
A13: Regression | B13: 1 | C13: 0.0011788527 | D13: 0.0011788527 | E13: 12.333289 | F13: 0.00048517459 | K13: Pull this number as the yield on corporate bonds at the time of your valuation.
A14: Residual | B14: 501 | C14: 0.04788708 | D14: 9.5582994e-05 | K14: Conversely, pull this number as the average yield on bonds with your firm's rating.
A15: Total | B15: 502 | C15: 0.049065933
K16: Rating | L16: AAA
B17: Coefficients | C17: Standard Error | D17: t Stat | E17: P-value | F17: Lower 95% | G17: Upper 95% | H17: Lower 95.0% | I17: Upper 95.0% | K17: Yield | L17: 0.0516
A18: Intercept | B18: -0.00025751031 | C18: 0.00043847028 | D18: -0.58729251 | E18: 0.55727184 | F18: -0.0011189774 | G18: 0.00060395677 | H18: -0.0011189774 | I18: 0.00060395677
A19: X Variable 1 | B19: 0.18324036 | C19: 0.05217731 | D19: 3.5118783 | E19: 0.00048517459 | F19: 0.080727064 | G19: 0.28575366 | H19: 0.080727064 | I19: 0.28575366
A21: Estimate Equity Risk Premium | K21: Financing Structure
A22: You can do this yourself or grab it from a reputable source: | K22: Mkt Value of Equity | M22: 368607000000
K23: Mkt Value of Debt | M23: 3575000000
A24: 2024 United States ERP
A25: 0.0412
K26: WACC
A27: Estimate Risk Free Rate | K27: =K10*(M22/(M22+M23))+L17*(M23/(M22+M23)) -> 0.050460554
A28: Take the U.S. treasury yield for the time horizon of your valuation
A29: 5 - year Treasury Yield
A30: 0.0429

Sheet Firm Returns 
A1: Date | B1: Open | C1: High | D1: Low | E1: Close | F1: Adj Close | G1: Volume | H1: Adj Ret
A2: 45617 | B2: 153.62 | C2: 156.05 | D2: 152.85 | E2: 155.5 | F2: 155.5 | G2: 6508808 | H2: =(F2-F3)/F3 -> 0.015609692
A3: 45616 | B3: 153.03 | C3: 153.25 | D3: 151.81 | E3: 153.11 | F3: 153.11 | G3: 9061300 | H3: =(F3-F4)/F4 -> 0.00071895425
A4: 45615 | B4: 153.95 | C4: 153.99 | D4: 152.05 | E4: 153 | F4: 153 | G4: 8233700 | H4: =(F4-F5)/F5 -> -0.011436325
A5: 45614 | B5: 152.59 | C5: 155.33 | D5: 152.33 | E5: 154.77 | F5: 154.77 | G5: 7514200 | H5: =(F5-F6)/F6 -> 0.005 | L5: Sharpe Ratio | N5: Average Return | P5: Standard deviation
A6: 45611 | B6: 150.9 | C6: 154.43 | D6: 150.9 | E6: 154 | F6: 154 | G6: 11328500 | H6: =(F6-F7)/F7 -> 0.014025153 | L6: =N6/P6 -> -0.0092640267 | N6: =AVERAGE(H2:H504) -> -9.1656332e-05 | P6: =_xlfn.STDEV.S(H2:H503) -> 0.0098937896
A7: 45610 | B7: 153.18 | C7: 153.59 | D7: 150.76 | E7: 151.87 | F7: 151.87 | G7: 7716400 | H7: =(F7-F8)/F8 -> -0.0089402245
A8: 45609 | B8: 152.5 | C8: 153.51 | D8: 151.42 | E8: 153.24 | F8: 153.24 | G8: 7161900 | H8: =(F8-F9)/F9 -> 0.0039308176
A9: 45608 | B9: 154.53 | C9: 155.04 | D9: 152.37 | E9: 152.64 | F9: 152.64 | G9: 7181400 | H9: =(F9-F10)/F10 -> -0.015479876
A10: 45607 | B10: 155.62 | C10: 157.58 | D10: 154.91 | E10: 155.04 | F10: 155.04 | G10: 7146800 | H10: =(F10-F11)/F11 -> -0.0027658069
A11: 45604 | B11: 157 | C11: 157.08 | D11: 155.41 | E11: 155.47 | F11: 155.47 | G11: 8926100 | H11: =(F11-F12)/F12 -> -0.0080393033
A12: 45603 | B12: 158.47 | C12: 158.75 | D12: 156.51 | E12: 156.73 | F12: 156.73 | G12: 7522800 | H12: =(F12-F13)/F13 -> -0.0072840132
A13: 45602 | B13: 159.9 | C13: 160.85 | D13: 157.35 | E13: 157.88 | F13: 157.88 | G13: 8926600 | H13: =(F13-F14)/F14 -> -0.0029681086
A14: 45601 | B14: 157.67 | C14: 158.59 | D14: 156.35 | E14: 158.35 | F14: 158.35 | G14: 6547100 | H14: =(F14-F15)/F15 -> 0.00069514661
A15: 45600 | B15: 159.7 | C15: 160.28 | D15: 158.07 | E15: 158.24 | F15: 158.24 | G15: 4644000 | H15: =(F15-F16)/F16 -> -0.01180291
A16: 45597 | B16: 160.58 | C16: 161.06 | D16: 159.88 | E16: 160.13 | F16: 160.13 | G16: 5256400 | H16: =(F16-F17)/F17 -> 0.0016889779
A17: 45596 | B17: 159.99 | C17: 160.87 | D17: 159.46 | E17: 159.86 | F17: 159.86 | G17: 8613900 | H17: =(F17-F18)/F18 -> -0.0046696968
A18: 45595 | B18: 159.45 | C18: 161.28 | D18: 159.03 | E18: 160.61 | F18: 160.61 | G18: 5820500 | H18: =(F18-F19)/F19 -> 0.0032481729
... A505: 44886 | B505: 175.89 | C505: 176.55 | D505: 174.83 | E505: 175.97 | F505: 166.87 | G505: 5706600 | H505: =(F505-F506)/F506 -> #DIV/0!

Sheet Market Returns
A1: Date | B1: Open | C1: High | D1: Low | E1: Close | F1: Adj Close | G1: Volume | H1: Adj Ret | K1: Here I use SPY returns to proxy for market returns.
A2: 45617 | B2: 5940.58 | C2: 5963.32 | D2: 5887.26 | E2: 5948.71 | F2: 5948.71 | G2: 2857014000 | H2: =(F2-F3)/F3 -> 0.0053404449 | K2: Make sure you update the dates so they are the same as your inputted firm returns.
A3: 45616 | B3: 5914.34 | C3: 5920.67 | D3: 5860.56 | E3: 5917.11 | F3: 5917.11 | G3: 3772620000 | H3: =(F3-F4)/F4 -> 2.1970667e-05
A4: 45615 | B4: 5870.05 | C4: 5923.51 | D4: 5855.29 | E4: 5916.98 | F4: 5916.98 | G4: 4036940000 | H4: =(F4-F5)/F5 -> 0.0039636081
A5: 45614 | B5: 5874.17 | C5: 5908.12 | D5: 5865.95 | E5: 5893.62 | F5: 5893.62 | G5: 3983860000 | H5: =(F5-F6)/F6 -> 0.0039178145
A6: 45611 | B6: 5912.79 | C6: 5915.32 | D6: 5853.01 | E6: 5870.62 | F6: 5870.62 | G6: 4590960000 | H6: =(F6-F7)/F7 -> -0.013203523
A7: 45610 | B7: 5989.68 | C7: 5993.88 | D7: 5942.28 | E7: 5949.17 | F7: 5949.17 | G7: 4184570000 | H7: =(F7-F8)/F8 -> -0.0060497412
A8: 45609 | B8: 5985.75 | C8: 6008.19 | D8: 5965.91 | E8: 5985.38 | F8: 5985.38 | G8: 4220180000 | H8: =(F8-F9)/F9 -> 0.00023228648 | L8: Sharp Ratio | N8: Avg | P8: Standard Deviation
A9: 45608 | B9: 6003.6 | C9: 6009.92 | D9: 5960.08 | E9: 5983.99 | F9: 5983.99 | G9: 4243400000 | H9: =(F9-F10)/F10 -> -0.0028926825 | L9: =N9/P9 -> 0.10132684 | N9: =AVERAGE(H2:H504) -> 0.00084946311 | P9: =_xlfn.STDEV.S(H2:H504) -> 0.0083833965
A10: 45607 | B10: 6008.86 | C10: 6017.31 | D10: 5986.69 | E10: 6001.35 | F10: 6001.35 | G10: 4333000000 | H10: =(F10-F11)/F11 -> 0.00096905366
A11: 45604 | B11: 5976.76 | C11: 6012.45 | D11: 5976.76 | E11: 5995.54 | F11: 5995.54 | G11: 4666740000 | H11: =(F11-F12)/F12 -> 0.0037568432
A12: 45603 | B12: 5947.21 | C12: 5983.84 | D12: 5947.21 | E12: 5973.1 | F12: 5973.1 | G12: 4925740000 | H12: =(F12-F13)/F13 -> 0.0074312199
A13: 45602 | B13: 5864.89 | C13: 5936.14 | D13: 5864.89 | E13: 5929.04 | F13: 5929.04 | G13: 6329530000 | H13: =(F13-F14)/F14 -> 0.025295879
A14: 45601 | B14: 5722.43 | C14: 5783.44 | D14: 5722.1 | E14: 5782.76 | F14: 5782.76 | G14: 3768310000 | H14: =(F14-F15)/F15 -> 0.012265675
A15: 45600 | B15: 5725.15 | C15: 5741.43 | D15: 5696.51 | E15: 5712.69 | F15: 5712.69 | G15: 3602060000 | H15: =(F15-F16)/F16 -> -0.0028121072
A16: 45597 | B16: 5723.22 | C16: 5772.52 | D16: 5723.22 | E16: 5728.8 | F16: 5728.8 | G16: 3796450000 | H16: =(F16-F17)/F17 -> 0.0040925781
A17: 45596 | B17: 5775.34 | C17: 5775.34 | D17: 5702.86 | E17: 5705.45 | F17: 5705.45 | G17: 4425660000 | H17: =(F17-F18)/F18 -> -0.018614748
A18: 45595 | B18: 5832.65 | C18: 5850.94 | D18: 5811.28 | E18: 5813.67 | F18: 5813.67 | G18: 3851120000 | H18: =(F18-F19)/F19 -> -0.0033002338
A19: 45594 | B19: 5819.68 | C19: 5847.19 | D19: 5802.17 | E19: 5832.92 | F19: 5832.92 | G19: 3879100000 | H19: =(F19-F20)/F20 -> 0.001614144
A20: 45593 | B20: 5833.93 | C20: 5842.92 | D20: 5823.08 | E20: 5823.52 | F20: 5823.52 | G20: 3691280000 | H20: =(F20-F21)/F21 -> 0.0026514604
A21: 45590 | B21: 5826.75 | C21: 5862.82 | D21: 5799.98 | E21: 5808.12 | F21: 5808.12 | G21: 3501280000 | H21: =(F21-F22)/F22 -> -0.00029949087
... A505: 44886 | B505: 3956.23 | C505: 3962 | D505: 3933.34 | E505: 3949.94 | F505: 3949.94 | G505: 3850690000 | H505: =(F505-F506)/F506 -> #DIV/0!
